Workbook

Sheet Istruzioni
B1: Comune di Ottaviano – Settore Urbanistica ed Edilizia Privata
B2: Scheda anonima di istruttoria – Istruzioni di compilazione (v1, 20/10/2026)
B3: Istruttoria di supporto: decisione e firma restano al responsabile del procedimento.
B5: A cosa serve
B6: La scheda contiene solo dati oggettivi della pratica. Viene letta da Claude (Project «Valutazione Pratiche Urbanistiche») che la confronta con la sintesi normativa e prepara il parere di fattibilità. Una scheda = una pratica = una chat.
B7: Come compilare (pochi minuti)
B8: 1. Compilare il foglio «Scheda», colonna D «Valore da compilare». Dove c'è la freccia del menu a tendina, scegliere un valore dall'elenco; non digitare altro.
B9: 2. Cominciare dal blocco A (codice pratica, tipo di procedimento, qualificazione). Dal tipo di procedimento e dalla qualificazione dipende quali campi sono richiesti.
B10: 3. Rispondere agli 8 interruttori «Sezione … pertinente?» (blocchi H, I, K, L, M, N, S, P): «No» salta l'intera sezione (le righe diventano grigie); «Sì» richiede i suoi campi.
B11: 4. La colonna «Obbligatorio per» dice per quali procedimenti il campo serve. Le sigle tra parentesi quadre: [parametri] = intervento che incide su volumi, sagoma, superfici; [uso/carico] = può cambiare destinazione d'uso o carico insediativo; [dem.-ric.] = demolizione e ricostruzione; [tetto] = intervento «tetto». Le qualificazioni con questi flag sono nel foglio «Elenchi».
B12: 5. Le celle rosse sono dati obbligatori mancanti; le gialle sono dati dichiarati «non noti». In alto alla scheda c'è il conteggio. Il foglio «Controlli» elenca i campi e le segnalazioni automatiche.
B13: 6. Le celle grigio-azzurre (corsivo) sono precompilate o calcolate: non modificarle. I dati noti per Ottaviano (zona sismica 2, zona rossa, vincolo paesaggistico su tutto il territorio, PSAI 2015, delibera oneri n. 17/2025) stanno nel blocco Z.
... B29: ESEMPIO FITTIZIO: dati inventati, solo per collaudo. Nessun riferimento a pratiche o persone reali.

Sheet Scheda_1
C1: Comune di Ottaviano – Settore Urbanistica ed Edilizia Privata
C2: Esempio 1 – SCIA cambio d'uso senza opere – valutazione pratiche urbanistiche (v1)
C3: Istruttoria di supporto: decisione e firma restano al responsabile del procedimento. Nessun dato personale.
C5: ="Dati obbligatori mancanti: "&Controlli_1!$B$13&" – dati dichiarati «non noti»: "&Controlli_1!$B$14&" – campi richiesti per questo procedimento: "&Controlli_1!$B$11 -> Dati obbligatori mancanti: 0 – dati dichiarati «non noti»: 0 – campi richiesti per questo procedimento: 41
A6: Codice | B6: Sezione | C6: Campo | D6: Valore da compilare | E6: Unità | F6: Obbligatorio per | G6: Nota (riferimento alla sintesi normativa) | H6: Stato
A7: Z – Dati noti per Ottaviano (precompilati, non modificare)
A8: Costanti del Comune: non vanno compilate.
A9: Z01 | B9: Dati noti per Ottaviano | C9: Zona sismica | D9: 2 | F9: — | G9: Sez. 14.7, 24 (conferma dell'utente) | H9: =Controlli_1!$L$33
A10: Z02 | B10: Dati noti per Ottaviano | C10: Zona rossa vesuviana (LR 21/2003) | D10: Sì – Ottaviano compreso | F10: — | G10: Sez. 17; la LR 21/2003 resta in vigore (PPR non in vigore: sez. 8 n. 28) | H10: =Controlli_1!$L$34
A11: Z03 | B11: Dati noti per Ottaviano | C11: Vincolo paesaggistico | D11: Intero territorio (art. 134 lett. b/c; art. 142 lett. f, l D.Lgs 42/04; D.M. 02/09/1961) | F11: — | G11: Sez. 13, 37.1 | H11: =Controlli_1!$L$35
A12: Z04 | B12: Dati noti per Ottaviano | C12: PSAI vigente | D12: Versione 2015 (Delib. C.I. n. 1 del 23/02/2015): si valuta il solo rischio | F12: — | G12: Sez. 5, 5 bis; CLAUDE.md sez. 4 | H12: =Controlli_1!$L$36
A13: Z05 | B13: Dati noti per Ottaviano | C13: Funzioni sismiche | D13: Commissione sismica comunale attiva | F13: — | G13: Sez. 36; sez. 8 n. 28 | H13: =Controlli_1!$L$37
A14: Z06 | B14: Dati noti per Ottaviano | C14: Delibera oneri e K2 | D14: Delibera n. 17 del 15/12/2025; K2 = 0,59 | F14: — | G14: Sez. 29, 8 n. 22 e 27 | H14: =Controlli_1!$L$38
A15: Z07 | B15: Dati noti per Ottaviano | C15: Prevalenza NTA / RUEC | D15: Tra NTA e RUEC prevalgono le NTA | F15: — | G15: CLAUDE.md sez. 2 punto 4; sez. 8 n. 1 e 27 | H15: =Controlli_1!$L$39
A16: A – Procedimento
A17: Sempre da compilare.
A18: A01 | B18: Procedimento | C18: Codice pratica anonimo (scelto dall'ufficio, senza nomi né numeri di protocollo identificativi) | D18: ESEMPIO-FITTIZIO-01 | F18: Tutti | G18: Sez. 10 A | H18: =Controlli_1!$L$40 -> ok | I18: 1
A19: A02 | B19: Procedimento | C19: Tipo di procedimento | D19: SCIA | F19: Tutti | G19: Sez. 10 A1; 7, 12, 14, 32 | H19: =Controlli_1!$L$41 -> ok | I19: 1
A20: A03 | B20: Procedimento | C20: Qualificazione dell'intervento (DPR 380/2001) | D20: Cambio d'uso senza opere | F20: Ordinari; Accertamento | G20: Sez. 10 A2; 14.1, 28.3, 32. Per i condoni vale la tipologia di illecito (sez. H) | H20: =Controlli_1!$L$42 -> ok | I20: 1
A21: A04 | B21: Procedimento | C21: Descrizione sintetica delle opere (solo dati tecnici, nessun dato personale) | D21: ESEMPIO FITTIZIO: cambio di destinazione d'uso senza opere di un'unità di 85 mq al piano terra, da ufficio (terziario) a negozio (commerciale). | F21: Ordinari; Condoni; Accertamento | G21: Sez. 10 A3 | H21: =Controlli_1!$L$43 -> ok | I21: 1
A22: A05 | B22: Procedimento | C22: Data di presentazione della domanda / del titolo | D22: 46279 | F22: Tutti | G22: Sez. 10 A4; 14.2; per la SCIA/CILA decorrenza della delibera oneri (29.1) | H22: =Controlli_1!$L$44 -> ok | I22: 1
A23: A06 | B23: Procedimento | C23: Data di rilascio del PdC (solo PdC; decorrenza della delibera oneri) | F23: Ordinari – solo se PdC | G23: Sez. 10 A4; 29.1 | H23: =Controlli_1!$L$45 | I23: 1
A24: B – Localizzazione urbanistica e vincoli
A25: Tutto il territorio è vincolato paesaggisticamente (costante Z03): qui solo ciò che varia da pratica a pratica.
A26: B01 | B26: Localizzazione urbanistica e vincoli | C26: Ambito PUC (articolo NTA) | D26: Art. 15 – Urbani consolidati | F26: Ordinari; Condoni; Accertamento | G26: Sez. 3, 28, 35.0 | H26: =Controlli_1!$L$46 -> ok | I26: 1
A27: B02 | B27: Localizzazione urbanistica e vincoli | C27: Zona omogenea A-F di default (calcolata dall'ambito) | D27: =IFERROR(VLOOKUP(Scheda_1!$D$26,Elenchi!$J$2:$N$40,3,FALSE())&"","") -> B | F27: — | G27: Sez. 35.0 (assimilazione, non norma). Cella calcolata: non compilare | H27: =Controlli_1!$L$47 | I27: 1
A28: B03 | B28: Localizzazione urbanistica e vincoli | C28: Zona omogenea A-F, se nota (prevale sul default dell'ambito) | F28: Facoltativo | G28: Sez. 35.0 e 35.6: la zona della scheda prevale | H28: =Controlli_1!$L$48 | I28: 1
A29: B04 | B29: Localizzazione urbanistica e vincoli | C29: Zona omogenea applicata (calcolata) | D29: =IF(Scheda_1!$D$28<>"",Scheda_1!$D$28,Scheda_1!$D$27) -> B | F29: — | G29: Cella calcolata: zona della scheda, altrimenti default dell'ambito. Se vuota e serve il K3, il parere la elenca come dato mancante | H29: =Controlli_1!$L$49 | I29: 1
A30: B05 | B30: Localizzazione urbanistica e vincoli | C30: Zona PTP | D30: Fuori perimetro PTP | F30: Ordinari; Condoni; Accertamento | G30: Sez. 4; NTA art. 3 c. 2-3 | H30: =Controlli_1!$L$50 -> ok | I30: 1
A31: B06 | B31: Localizzazione urbanistica e vincoli | C31: Rapporto con il Parco Nazionale del Vesuvio | D31: Fuori | F31: Ordinari; Condoni; Accertamento | G31: Sez. 4, 32.2 (nulla osta Ente Parco) | H31: =Controlli_1!$L$51 -> ok | I31: 1
A32: B07 | B32: Localizzazione urbanistica e vincoli | C32: Interessa SIC/ZPS | D32: No | F32: Ordinari; Condoni; Accertamento | G32: Sez. 4 | H32: =Controlli_1!$L$52 -> ok | I32: 1
A33: B08 | B33: Localizzazione urbanistica e vincoli | C33: Area boscata | D33: No | F33: Ordinari; Condoni; Accertamento | G33: Sez. 4 | H33: =Controlli_1!$L$53 -> ok | I33: 1
A34: B09 | B34: Localizzazione urbanistica e vincoli | C34: Area archeologica | D34: No | F34: Ordinari; Condoni; Accertamento | G34: Sez. 4 | H34: =Controlli_1!$L$54 -> ok | I34: 1
A35: B10 | B35: Localizzazione urbanistica e vincoli | C35: Immobile bene culturale (art. 10 D.Lgs 42/04) o soggetto a tutela indiretta (artt. 45-47) | D35: No | F35: Ordinari; Condoni; Accertamento | G35: Sez. 10 B7 e B10; 13.5, 13.8 | H35: =Controlli_1!$L$55 -> ok | I35: 1
A36: B11 | B36: Localizzazione urbanistica e vincoli | C36: Fascia di rispetto interessata | F36: Ordinari [parametri]; Condoni; Accertamento [parametri] | G36: Sez. 4; 8 n. 2 (fasce stradali). Se più di una, indicarle nella descrizione | H36: =Controlli_1!$L$56 | I36: 1
A37: B12 | B37: Localizzazione urbanistica e vincoli | C37: Distanza dalla fascia / dall'elemento vincolante | E37: m | F37: Ordinari [parametri]; Accertamento [parametri] – solo se c'è una fascia | G37: Sez. 10 B8 | H37: =Controlli_1!$L$57 | I37: 1
A38: B13 | B38: Localizzazione urbanistica e vincoli | C38: Vincolo paesaggistico rafforzato (provvedimento specifico oltre al vincolo generale) | D38: No | F38: Ordinari; Condoni; Accertamento | G38: Sez. 13.8 | H38: =Controlli_1!$L$58 -> ok | I38: 1
A39: B14 | B39: Localizzazione urbanistica e vincoli | C39: Data di istituzione del vincolo paesaggistico applicabile all'immobile | F39: Condoni; Accertamento | G39: OBBLIGATORIO: CLAUDE.md sez. 4; sez. 12.3, 12.9. Va confrontata con la data delle opere (Controlli) | H39: =Controlli_1!$L$59 | I39: 1
A40: B15 | B40: Localizzazione urbanistica e vincoli | C40: Data di istituzione del vincolo del Parco (o «non applicabile» se fuori Parco) | F40: Condoni; Accertamento | G40: OBBLIGATORIO: sez. 10 B11 | H40: =Controlli_1!$L$60 | I40: 1
A41: B16 | B41: Localizzazione urbanistica e vincoli | C41: Data di istituzione di altri vincoli presenti (idrogeologico, archeologico, ecc.; o «non applicabile») | F41: Condoni; Accertamento | G41: OBBLIGATORIO: sez. 10 B11 | H41: =Controlli_1!$L$61 | I41: 1
...

Sheet Controlli_1
A1: Controlli – dati mancanti e segnalazioni automatiche
A2: Le formule leggono il foglio «Scheda_1». Un campo obbligatorio vuoto è «MANCANTE» (rosso); «non noto» è accettato ma contato a parte. Le segnalazioni non sostituiscono la verifica del funzionario.
A3: Riepilogo
A4: Proc. | B4: =Scheda_1!$D$19&"" -> SCIA
A5: Gruppo | B5: =IFERROR(VLOOKUP(Scheda_1!$D$19,Elenchi!$A$2:$B$12,2,FALSE()),"") -> ORD | C5: Gruppo del procedimento (ORD / CON / AGI / ACC)
A6: Parametri | B6: =IFERROR(VLOOKUP(Scheda_1!$D$20,Elenchi!$D$2:$H$40,2,FALSE()),0) -> 0 | C6: Qualificazione con parametri edilizi (1 = sì)
A7: Uso/carico | B7: =IFERROR(VLOOKUP(Scheda_1!$D$20,Elenchi!$D$2:$H$40,3,FALSE()),0) -> 1 | C7: Qualificazione che può cambiare uso o carico (1 = sì)
A8: Dem.-ric. | B8: =IFERROR(VLOOKUP(Scheda_1!$D$20,Elenchi!$D$2:$H$40,4,FALSE()),0) -> 0 | C8: Demolizione e ricostruzione (1 = sì)
A9: Tetto | B9: =IFERROR(VLOOKUP(Scheda_1!$D$20,Elenchi!$D$2:$H$40,5,FALSE()),0) -> 0 | C9: Intervento «tetto» (1 = sì)
A11: Obbligatori | B11: =SUM(K33:K253) -> 41 | C11: campi richiesti per questo procedimento
A12: Compilati | B12: =COUNTIF(L33:L253,"ok") -> 41 | C12: campi richiesti e compilati
A13: MANCANTI | B13: =COUNTIF(L33:L253,"MANCANTE") -> 0 | C13: campi richiesti e vuoti
A14: Non noti | B14: =COUNTIF(L33:L253,"NON NOTO") -> 0 | C14: campi richiesti con valore «non noto»
A16: Segnalazioni automatiche (vuote = nessuna)
A17: Zona A-F | B17: =IF(Scheda_1!$D$29<>"","Zona applicata: "&Scheda_1!$D$29&IF(Scheda_1!$D$28<>""," (dalla scheda, prevale)"," (default dell'ambito, sez. 35.0)"),"Zona A-F non determinata: se serve il K3 indicarla nel campo «zona omogenea»") -> Zona applicata: B (default dell'ambito, sez. 35.0)
A18: Vincolo/opere | B18: =IF(OR($B$5="CON",$B$5="ACC"),IF(AND(ISNUMBER(Scheda_1!$D$39),ISNUMBER(Scheda_1!$D$62)),IF(Scheda_1!$D$39<=Scheda_1!$D$62,"Vincolo paesaggistico ANTERIORE alle opere (sez. 12.9, 13.2)","Vincolo paesaggistico POSTERIORE alle opere (sez. 12.9, 13.2)"),"Data di istituzione del vincolo o data delle opere mancante: confronto non possibile"),"")
A19: Sez. H | B19: =IF(AND($B$5="CON",Scheda_1!$D$145<>"Sì"),"ATTENZIONE: procedimento di condono, attivare la sezione H","")
A20: Sez. M | B20: =IF(AND(Scheda_1!$D$19="Edilizia libera",Scheda_1!$D$217<>"Sì"),"ATTENZIONE: edilizia libera, attivare la sezione M","")
A21: Sez. I | B21: =IF(AND(Scheda_1!$D$20="Recupero abitativo del sottotetto",Scheda_1!$D$171<>"Sì"),"ATTENZIONE: recupero del sottotetto, attivare la sezione I","")
A22: Sez. S | B22: =IF(AND(Scheda_1!$D$52="Sì",Scheda_1!$D$236<>"Sì"),"ATTENZIONE: lavori su parti strutturali, attivare la sezione S","")
A23: Sismica | B23: =IF(Scheda_1!$D$236<>"Sì","",IF(Scheda_1!$D$239="Sì","Autorizzazione sismica: Genio Civile (istanza già inoltrata prima del 01/11/2025, LR 26/2025)",IF(OR(AND(ISNUMBER(Scheda_1!$D$237),Scheda_1!$D$237>16.5),AND(ISNUMBER(Scheda_1!$D$238),Scheda_1!$D$238>4)),"Autorizzazione sismica: Genio Civile (oltre i limiti LR 26/2025: 16,50 m / 4,00 m)",IF(AND(ISNUMBER(Scheda_1!$D$237),ISNUMBER(Scheda_1!$D$238)),"Autorizzazione sismica: Comune (commissione sismica attiva, entro i limiti LR 26/2025)","Competenza sismica non determinabile: altezza strutturale o profondità interrata mancante"))))
A24: PSAI R3/R4 | B24: =IF(OR(Scheda_1!$D$46="R3",Scheda_1!$D$46="R4",Scheda_1!$D$47="R3",Scheda_1!$D$47="R4"),"Rischio PSAI R3/R4: sez. 5 e 5 bis; incentivi di rigenerazione esclusi (art. 33 quater LR 16/2004)","")
A25: Rischio atteso | B25: =IF(AND(OR(AND(Scheda_1!$D$46<>"",Scheda_1!$D$46<>"Nessuno",Scheda_1!$D$46<>"Non noto"),AND(Scheda_1!$D$47<>"",Scheda_1!$D$47<>"Nessuno",Scheda_1!$D$47<>"Non noto")),OR($B$6=1,$B$7=1)),"Intervento nuovo o con aumento di carico in area a rischio: segnalare la verifica del rischio atteso PSAI senza concludere (sez. 8 n. 27)","")
A26: Condono pend. | B26: =IF(Scheda_1!$D$242<>"Sì","",IF(OR(Scheda_1!$D$245="Sì",Scheda_1!$D$246="Sì",Scheda_1!$D$247="Sì",Scheda_1!$D$244="Altro (eccedente)"),"Delibera C.C. 22/2023: intervento oltre i limiti, servono fascicolo integrato, valutazione NTC 8.3, autodichiarazione e perizia giurata (sez. 37.2)","Delibera C.C. 22/2023: intervento entro i limiti di MO, MS, efficientamento, restauro; verificare le quattro condizioni (sez. 37.2)"))
A27: Date | B27: =IF(AND(ISNUMBER(Scheda_1!$D$62),ISNUMBER(Scheda_1!$D$22),Scheda_1!$D$62>Scheda_1!$D$22),"ATTENZIONE: data di realizzazione successiva alla data di presentazione","")
A28: Zona rossa | B28: =IF(OR(Scheda_1!$D$119="Sì",Scheda_1!$D$98="Sì"),"ATTENZIONE: aumento di volumi abitabili o mutamento d'uso verso l'abitativo in zona rossa (LR 21/2003, sez. 17)","")
A29: K3 | B29: =IF(AND(Scheda_1!$D$193="Sì",Scheda_1!$D$29=""),"Contributo: zona omogenea A-F non determinata, indicarla nella scheda (sez. 29.3, 35)","")
A31: Regole per campo (X = sempre; P, C, DR, T = solo se la qualificazione ha quel flag, vedi Elenchi)
A32: Codice | B32: Campo | C32: Sezione | D32: ORD | E32: CON | F32: AGI | G32: ACC | H32: Pertinente | I32: Condizione | J32: Regola | K32: Obbligatorio | L32: Stato
A33: Z01 | B33: Zona sismica | C33: Dati noti per Ottaviano | H33: 1 | I33: 1 | J33: =IF($B$5="","",IF($B$5="ORD",D33,IF($B$5="CON",E33,IF($B$5="AGI",F33,G33)))) -> 0 | K33: 0 | L33: =IF(K33=0,"",IF(LEN(TRIM(Scheda_1!$D$9&""))=0,"MANCANTE",IF(LEFT(LOWER(TRIM(Scheda_1!$D$9&"")),7)="non not","NON NOTO","ok")))
A34: Z02 | B34: Zona rossa vesuviana (LR 21/2003) | C34: Dati noti per Ottaviano | H34: 1 | I34: 1 | J34: =IF($B$5="","",IF($B$5="ORD",D34,IF($B$5="CON",E34,IF($B$5="AGI",F34,G34)))) -> 0 | K34: 0 | L34: =IF(K34=0,"",IF(LEN(TRIM(Scheda_1!$D$10&""))=0,"MANCANTE",IF(LEFT(LOWER(TRIM(Scheda_1!$D$10&"")),7)="non not","NON NOTO","ok")))
A35: Z03 | B35: Vincolo paesaggistico | C35: Dati noti per Ottaviano | H35: 1 | I35: 1 | J35: =IF($B$5="","",IF($B$5="ORD",D35,IF($B$5="CON",E35,IF($B$5="AGI",F35,G35)))) -> 0 | K35: 0 | L35: =IF(K35=0,"",IF(LEN(TRIM(Scheda_1!$D$11&""))=0,"MANCANTE",IF(LEFT(LOWER(TRIM(Scheda_1!$D$11&"")),7)="non not","NON NOTO","ok")))
A36: Z04 | B36: PSAI vigente | C36: Dati noti per Ottaviano | H36: 1 | I36: 1 | J36: =IF($B$5="","",IF($B$5="ORD",D36,IF($B$5="CON",E36,IF($B$5="AGI",F36,G36)))) -> 0 | K36: 0 | L36: =IF(K36=0,"",IF(LEN(TRIM(Scheda_1!$D$12&""))=0,"MANCANTE",IF(LEFT(LOWER(TRIM(Scheda_1!$D$12&"")),7)="non not","NON NOTO","ok")))
A37: Z05 | B37: Funzioni sismiche | C37: Dati noti per Ottaviano | H37: 1 | I37: 1 | J37: =IF($B$5="","",IF($B$5="ORD",D37,IF($B$5="CON",E37,IF($B$5="AGI",F37,G37)))) -> 0 | K37: 0 | L37: =IF(K37=0,"",IF(LEN(TRIM(Scheda_1!$D$13&""))=0,"MANCANTE",IF(LEFT(LOWER(TRIM(Scheda_1!$D$13&"")),7)="non not","NON NOTO","ok")))
A38: Z06 | B38: Delibera oneri e K2 | C38: Dati noti per Ottaviano | H38: 1 | I38: 1 | J38: =IF($B$5="","",IF($B$5="ORD",D38,IF($B$5="CON",E38,IF($B$5="AGI",F38,G38)))) -> 0 | K38: 0 | L38: =IF(K38=0,"",IF(LEN(TRIM(Scheda_1!$D$14&""))=0,"MANCANTE",IF(LEFT(LOWER(TRIM(Scheda_1!$D$14&"")),7)="non not","NON NOTO","ok")))
A39: Z07 | B39: Prevalenza NTA / RUEC | C39: Dati noti per Ottaviano | H39: 1 | I39: 1 | J39: =IF($B$5="","",IF($B$5="ORD",D39,IF($B$5="CON",E39,IF($B$5="AGI",F39,G39)))) -> 0 | K39: 0 | L39: =IF(K39=0,"",IF(LEN(TRIM(Scheda_1!$D$15&""))=0,"MANCANTE",IF(LEFT(LOWER(TRIM(Scheda_1!$D$15&"")),7)="non not","NON NOTO","ok")))
A40: A01 | B40: Codice pratica anonimo (scelto dall'ufficio, senza nomi né numeri di protocollo identificativi) | C40: Procedimento | D40: X | E40: X | F40: X | G40: X | H40: 1 | I40: 1 | J40: =IF($B$5="","",IF($B$5="ORD",D40,IF($B$5="CON",E40,IF($B$5="AGI",F40,G40)))) -> X | K40: =IF(H40=1,1,0) -> 1 | L40: =IF(K40=0,"",IF(LEN(TRIM(Scheda_1!$D$18&""))=0,"MANCANTE",IF(LEFT(LOWER(TRIM(Scheda_1!$D$18&"")),7)="non not","NON NOTO","ok"))) -> ok
A41: A02 | B41: Tipo di procedimento | C41: Procedimento | D41: X | E41: X | F41: X | G41: X | H41: 1 | I41: 1 | J41: =IF($B$5="","",IF($B$5="ORD",D41,IF($B$5="CON",E41,IF($B$5="AGI",F41,G41)))) -> X | K41: =IF(H41=1,1,0) -> 1 | L41: =IF(K41=0,"",IF(LEN(TRIM(Scheda_1!$D$19&""))=0,"MANCANTE",IF(LEFT(LOWER(TRIM(Scheda_1!$D$19&"")),7)="non not","NON NOTO","ok"))) -> ok
A42: A03 | B42: Qualificazione dell'intervento (DPR 380/2001) | C42: Procedimento | D42: X | G42: X | H42: 1 | I42: 1 | J42: =IF($B$5="","",IF($B$5="ORD",D42,IF($B$5="CON",E42,IF($B$5="AGI",F42,G42)))) -> X | K42: =IF(OR(H42=0,I42=0,J42=""),0,IF(IF(J42="X",1,IF(J42="P",$B$6,IF(J42="C",$B$7,IF(J42="DR",$B$8,IF(J42="T",$B$9,0)))))=1,1,0)) -> 1 | L42: =IF(K42=0,"",IF(LEN(TRIM(Scheda_1!$D$20&""))=0,"MANCANTE",IF(LEFT(LOWER(TRIM(Scheda_1!$D$20&"")),7)="non not","NON NOTO","ok"))) -> ok
A43: A04 | B43: Descrizione sintetica delle opere (solo dati tecnici, nessun dato personale) | C43: Procedimento | D43: X | E43: X | G43: X | H43: 1 | I43: 1 | J43: =IF($B$5="","",IF($B$5="ORD",D43,IF($B$5="CON",E43,IF($B$5="AGI",F43,G43)))) -> X | K43: =IF(OR(H43=0,I43=0,J43=""),0,IF(IF(J43="X",1,IF(J43="P",$B$6,IF(J43="C",$B$7,IF(J43="DR",$B$8,IF(J43="T",$B$9,0)))))=1,1,0)) -> 1 | L43: =IF(K43=0,"",IF(LEN(TRIM(Scheda_1!$D$21&""))=0,"MANCANTE",IF(LEFT(LOWER(TRIM(Scheda_1!$D$21&"")),7)="non not","NON NOTO","ok"))) -> ok
...

Sheet Scheda_2
C1: Comune di Ottaviano – Settore Urbanistica ed Edilizia Privata
C2: Esempio 2 – CILA su immobile con condono pendente – valutazione pratiche urbanistiche (v1)
C3: Istruttoria di supporto: decisione e firma restano al responsabile del procedimento. Nessun dato personale.
C5: ="Dati obbligatori mancanti: "&Controlli_2!$B$13&" – dati dichiarati «non noti»: "&Controlli_2!$B$14&" – campi richiesti per questo procedimento: "&Controlli_2!$B$11 -> Dati obbligatori mancanti: 2 – dati dichiarati «non noti»: 2 – campi richiesti per questo procedimento: 44
A6: Codice | B6: Sezione | C6: Campo | D6: Valore da compilare | E6: Unità | F6: Obbligatorio per | G6: Nota (riferimento alla sintesi normativa) | H6: Stato
A7: Z – Dati noti per Ottaviano (precompilati, non modificare)
A8: Costanti del Comune: non vanno compilate.
A9: Z01 | B9: Dati noti per Ottaviano | C9: Zona sismica | D9: 2 | F9: — | G9: Sez. 14.7, 24 (conferma dell'utente) | H9: =Controlli_2!$L$33
A10: Z02 | B10: Dati noti per Ottaviano | C10: Zona rossa vesuviana (LR 21/2003) | D10: Sì – Ottaviano compreso | F10: — | G10: Sez. 17; la LR 21/2003 resta in vigore (PPR non in vigore: sez. 8 n. 28) | H10: =Controlli_2!$L$34
A11: Z03 | B11: Dati noti per Ottaviano | C11: Vincolo paesaggistico | D11: Intero territorio (art. 134 lett. b/c; art. 142 lett. f, l D.Lgs 42/04; D.M. 02/09/1961) | F11: — | G11: Sez. 13, 37.1 | H11: =Controlli_2!$L$35
A12: Z04 | B12: Dati noti per Ottaviano | C12: PSAI vigente | D12: Versione 2015 (Delib. C.I. n. 1 del 23/02/2015): si valuta il solo rischio | F12: — | G12: Sez. 5, 5 bis; CLAUDE.md sez. 4 | H12: =Controlli_2!$L$36
A13: Z05 | B13: Dati noti per Ottaviano | C13: Funzioni sismiche | D13: Commissione sismica comunale attiva | F13: — | G13: Sez. 36; sez. 8 n. 28 | H13: =Controlli_2!$L$37
A14: Z06 | B14: Dati noti per Ottaviano | C14: Delibera oneri e K2 | D14: Delibera n. 17 del 15/12/2025; K2 = 0,59 | F14: — | G14: Sez. 29, 8 n. 22 e 27 | H14: =Controlli_2!$L$38
A15: Z07 | B15: Dati noti per Ottaviano | C15: Prevalenza NTA / RUEC | D15: Tra NTA e RUEC prevalgono le NTA | F15: — | G15: CLAUDE.md sez. 2 punto 4; sez. 8 n. 1 e 27 | H15: =Controlli_2!$L$39
A16: A – Procedimento
A17: Sempre da compilare.
A18: A01 | B18: Procedimento | C18: Codice pratica anonimo (scelto dall'ufficio, senza nomi né numeri di protocollo identificativi) | D18: ESEMPIO-FITTIZIO-02 | F18: Tutti | G18: Sez. 10 A | H18: =Controlli_2!$L$40 -> ok | I18: 1
A19: A02 | B19: Procedimento | C19: Tipo di procedimento | D19: CILA | F19: Tutti | G19: Sez. 10 A1; 7, 12, 14, 32 | H19: =Controlli_2!$L$41 -> ok | I19: 1
A20: A03 | B20: Procedimento | C20: Qualificazione dell'intervento (DPR 380/2001) | D20: Manutenzione straordinaria | F20: Ordinari; Accertamento | G20: Sez. 10 A2; 14.1, 28.3, 32. Per i condoni vale la tipologia di illecito (sez. H) | H20: =Controlli_2!$L$42 -> ok | I20: 1
A21: A04 | B21: Procedimento | C21: Descrizione sintetica delle opere (solo dati tecnici, nessun dato personale) | D21: ESEMPIO FITTIZIO: manutenzione straordinaria (rifacimento di intonaci e infissi interni) di un fabbricato con istanza di condono L. 47/85 non definita. | F21: Ordinari; Condoni; Accertamento | G21: Sez. 10 A3 | H21: =Controlli_2!$L$43 -> ok | I21: 1
A22: A05 | B22: Procedimento | C22: Data di presentazione della domanda / del titolo | D22: 46297 | F22: Tutti | G22: Sez. 10 A4; 14.2; per la SCIA/CILA decorrenza della delibera oneri (29.1) | H22: =Controlli_2!$L$44 -> ok | I22: 1
A23: A06 | B23: Procedimento | C23: Data di rilascio del PdC (solo PdC; decorrenza della delibera oneri) | F23: Ordinari – solo se PdC | G23: Sez. 10 A4; 29.1 | H23: =Controlli_2!$L$45 | I23: 1
A24: B – Localizzazione urbanistica e vincoli
A25: Tutto il territorio è vincolato paesaggisticamente (costante Z03): qui solo ciò che varia da pratica a pratica.
A26: B01 | B26: Localizzazione urbanistica e vincoli | C26: Ambito PUC (articolo NTA) | D26: Art. 16 – Urbani di riassetto, parti edificate | F26: Ordinari; Condoni; Accertamento | G26: Sez. 3, 28, 35.0 | H26: =Controlli_2!$L$46 -> ok | I26: 1
A27: B02 | B27: Localizzazione urbanistica e vincoli | C27: Zona omogenea A-F di default (calcolata dall'ambito) | D27: =IFERROR(VLOOKUP(Scheda_2!$D$26,Elenchi!$J$2:$N$40,3,FALSE())&"","") -> B | F27: — | G27: Sez. 35.0 (assimilazione, non norma). Cella calcolata: non compilare | H27: =Controlli_2!$L$47 | I27: 1
A28: B03 | B28: Localizzazione urbanistica e vincoli | C28: Zona omogenea A-F, se nota (prevale sul default dell'ambito) | D28: B | F28: Facoltativo | G28: Sez. 35.0 e 35.6: la zona della scheda prevale | H28: =Controlli_2!$L$48 | I28: 1
A29: B04 | B29: Localizzazione urbanistica e vincoli | C29: Zona omogenea applicata (calcolata) | D29: =IF(Scheda_2!$D$28<>"",Scheda_2!$D$28,Scheda_2!$D$27) -> B | F29: — | G29: Cella calcolata: zona della scheda, altrimenti default dell'ambito. Se vuota e serve il K3, il parere la elenca come dato mancante | H29: =Controlli_2!$L$49 | I29: 1
A30: B05 | B30: Localizzazione urbanistica e vincoli | C30: Zona PTP | D30: Fuori perimetro PTP | F30: Ordinari; Condoni; Accertamento | G30: Sez. 4; NTA art. 3 c. 2-3 | H30: =Controlli_2!$L$50 -> ok | I30: 1
A31: B06 | B31: Localizzazione urbanistica e vincoli | C31: Rapporto con il Parco Nazionale del Vesuvio | D31: Dentro | F31: Ordinari; Condoni; Accertamento | G31: Sez. 4, 32.2 (nulla osta Ente Parco) | H31: =Controlli_2!$L$51 -> ok | I31: 1
A32: B07 | B32: Localizzazione urbanistica e vincoli | C32: Interessa SIC/ZPS | D32: No | F32: Ordinari; Condoni; Accertamento | G32: Sez. 4 | H32: =Controlli_2!$L$52 -> ok | I32: 1
A33: B08 | B33: Localizzazione urbanistica e vincoli | C33: Area boscata | D33: No | F33: Ordinari; Condoni; Accertamento | G33: Sez. 4 | H33: =Controlli_2!$L$53 -> ok | I33: 1
A34: B09 | B34: Localizzazione urbanistica e vincoli | C34: Area archeologica | D34: No | F34: Ordinari; Condoni; Accertamento | G34: Sez. 4 | H34: =Controlli_2!$L$54 -> ok | I34: 1
A35: B10 | B35: Localizzazione urbanistica e vincoli | C35: Immobile bene culturale (art. 10 D.Lgs 42/04) o soggetto a tutela indiretta (artt. 45-47) | D35: No | F35: Ordinari; Condoni; Accertamento | G35: Sez. 10 B7 e B10; 13.5, 13.8 | H35: =Controlli_2!$L$55 -> ok | I35: 1
A36: B11 | B36: Localizzazione urbanistica e vincoli | C36: Fascia di rispetto interessata | F36: Ordinari [parametri]; Condoni; Accertamento [parametri] | G36: Sez. 4; 8 n. 2 (fasce stradali). Se più di una, indicarle nella descrizione | H36: =Controlli_2!$L$56 | I36: 1
A37: B12 | B37: Localizzazione urbanistica e vincoli | C37: Distanza dalla fascia / dall'elemento vincolante | E37: m | F37: Ordinari [parametri]; Accertamento [parametri] – solo se c'è una fascia | G37: Sez. 10 B8 | H37: =Controlli_2!$L$57 | I37: 1
A38: B13 | B38: Localizzazione urbanistica e vincoli | C38: Vincolo paesaggistico rafforzato (provvedimento specifico oltre al vincolo generale) | D38: No | F38: Ordinari; Condoni; Accertamento | G38: Sez. 13.8 | H38: =Controlli_2!$L$58 -> ok | I38: 1
A39: B14 | B39: Localizzazione urbanistica e vincoli | C39: Data di istituzione del vincolo paesaggistico applicabile all'immobile | F39: Condoni; Accertamento | G39: OBBLIGATORIO: CLAUDE.md sez. 4; sez. 12.3, 12.9. Va confrontata con la data delle opere (Controlli) | H39: =Controlli_2!$L$59 | I39: 1
A40: B15 | B40: Localizzazione urbanistica e vincoli | C40: Data di istituzione del vincolo del Parco (o «non applicabile» se fuori Parco) | F40: Condoni; Accertamento | G40: OBBLIGATORIO: sez. 10 B11 | H40: =Controlli_2!$L$60 | I40: 1
A41: B16 | B41: Localizzazione urbanistica e vincoli | C41: Data di istituzione di altri vincoli presenti (idrogeologico, archeologico, ecc.; o «non applicabile») | F41: Condoni; Accertamento | G41: OBBLIGATORIO: sez. 10 B11 | H41: =Controlli_2!$L$61 | I41: 1
...

Sheet Controlli_2
A1: Controlli – dati mancanti e segnalazioni automatiche
A2: Le formule leggono il foglio «Scheda_2». Un campo obbligatorio vuoto è «MANCANTE» (rosso); «non noto» è accettato ma contato a parte. Le segnalazioni non sostituiscono la verifica del funzionario.
A3: Riepilogo
A4: Proc. | B4: =Scheda_2!$D$19&"" -> CILA
A5: Gruppo | B5: =IFERROR(VLOOKUP(Scheda_2!$D$19,Elenchi!$A$2:$B$12,2,FALSE()),"") -> ORD | C5: Gruppo del procedimento (ORD / CON / AGI / ACC)
A6: Parametri | B6: =IFERROR(VLOOKUP(Scheda_2!$D$20,Elenchi!$D$2:$H$40,2,FALSE()),0) -> 0 | C6: Qualificazione con parametri edilizi (1 = sì)
A7: Uso/carico | B7: =IFERROR(VLOOKUP(Scheda_2!$D$20,Elenchi!$D$2:$H$40,3,FALSE()),0) -> 0 | C7: Qualificazione che può cambiare uso o carico (1 = sì)
A8: Dem.-ric. | B8: =IFERROR(VLOOKUP(Scheda_2!$D$20,Elenchi!$D$2:$H$40,4,FALSE()),0) -> 0 | C8: Demolizione e ricostruzione (1 = sì)
A9: Tetto | B9: =IFERROR(VLOOKUP(Scheda_2!$D$20,Elenchi!$D$2:$H$40,5,FALSE()),0) -> 0 | C9: Intervento «tetto» (1 = sì)
A11: Obbligatori | B11: =SUM(K33:K253) -> 44 | C11: campi richiesti per questo procedimento
A12: Compilati | B12: =COUNTIF(L33:L253,"ok") -> 40 | C12: campi richiesti e compilati
A13: MANCANTI | B13: =COUNTIF(L33:L253,"MANCANTE") -> 2 | C13: campi richiesti e vuoti
A14: Non noti | B14: =COUNTIF(L33:L253,"NON NOTO") -> 2 | C14: campi richiesti con valore «non noto»
A16: Segnalazioni automatiche (vuote = nessuna)
A17: Zona A-F | B17: =IF(Scheda_2!$D$29<>"","Zona applicata: "&Scheda_2!$D$29&IF(Scheda_2!$D$28<>""," (dalla scheda, prevale)"," (default dell'ambito, sez. 35.0)"),"Zona A-F non determinata: se serve il K3 indicarla nel campo «zona omogenea»") -> Zona applicata: B (dalla scheda, prevale)
A18: Vincolo/opere | B18: =IF(OR($B$5="CON",$B$5="ACC"),IF(AND(ISNUMBER(Scheda_2!$D$39),ISNUMBER(Scheda_2!$D$62)),IF(Scheda_2!$D$39<=Scheda_2!$D$62,"Vincolo paesaggistico ANTERIORE alle opere (sez. 12.9, 13.2)","Vincolo paesaggistico POSTERIORE alle opere (sez. 12.9, 13.2)"),"Data di istituzione del vincolo o data delle opere mancante: confronto non possibile"),"")
A19: Sez. H | B19: =IF(AND($B$5="CON",Scheda_2!$D$145<>"Sì"),"ATTENZIONE: procedimento di condono, attivare la sezione H","")
A20: Sez. M | B20: =IF(AND(Scheda_2!$D$19="Edilizia libera",Scheda_2!$D$217<>"Sì"),"ATTENZIONE: edilizia libera, attivare la sezione M","")
A21: Sez. I | B21: =IF(AND(Scheda_2!$D$20="Recupero abitativo del sottotetto",Scheda_2!$D$171<>"Sì"),"ATTENZIONE: recupero del sottotetto, attivare la sezione I","")
A22: Sez. S | B22: =IF(AND(Scheda_2!$D$52="Sì",Scheda_2!$D$236<>"Sì"),"ATTENZIONE: lavori su parti strutturali, attivare la sezione S","")
A23: Sismica | B23: =IF(Scheda_2!$D$236<>"Sì","",IF(Scheda_2!$D$239="Sì","Autorizzazione sismica: Genio Civile (istanza già inoltrata prima del 01/11/2025, LR 26/2025)",IF(OR(AND(ISNUMBER(Scheda_2!$D$237),Scheda_2!$D$237>16.5),AND(ISNUMBER(Scheda_2!$D$238),Scheda_2!$D$238>4)),"Autorizzazione sismica: Genio Civile (oltre i limiti LR 26/2025: 16,50 m / 4,00 m)",IF(AND(ISNUMBER(Scheda_2!$D$237),ISNUMBER(Scheda_2!$D$238)),"Autorizzazione sismica: Comune (commissione sismica attiva, entro i limiti LR 26/2025)","Competenza sismica non determinabile: altezza strutturale o profondità interrata mancante"))))
A24: PSAI R3/R4 | B24: =IF(OR(Scheda_2!$D$46="R3",Scheda_2!$D$46="R4",Scheda_2!$D$47="R3",Scheda_2!$D$47="R4"),"Rischio PSAI R3/R4: sez. 5 e 5 bis; incentivi di rigenerazione esclusi (art. 33 quater LR 16/2004)","")
A25: Rischio atteso | B25: =IF(AND(OR(AND(Scheda_2!$D$46<>"",Scheda_2!$D$46<>"Nessuno",Scheda_2!$D$46<>"Non noto"),AND(Scheda_2!$D$47<>"",Scheda_2!$D$47<>"Nessuno",Scheda_2!$D$47<>"Non noto")),OR($B$6=1,$B$7=1)),"Intervento nuovo o con aumento di carico in area a rischio: segnalare la verifica del rischio atteso PSAI senza concludere (sez. 8 n. 27)","")
A26: Condono pend. | B26: =IF(Scheda_2!$D$242<>"Sì","",IF(OR(Scheda_2!$D$245="Sì",Scheda_2!$D$246="Sì",Scheda_2!$D$247="Sì",Scheda_2!$D$244="Altro (eccedente)"),"Delibera C.C. 22/2023: intervento oltre i limiti, servono fascicolo integrato, valutazione NTC 8.3, autodichiarazione e perizia giurata (sez. 37.2)","Delibera C.C. 22/2023: intervento entro i limiti di MO, MS, efficientamento, restauro; verificare le quattro condizioni (sez. 37.2)")) -> Delibera C.C. 22/2023: intervento entro i limiti di MO, MS, efficientamento, restauro; verificare le quattro condizioni (sez. 37.2)
A27: Date | B27: =IF(AND(ISNUMBER(Scheda_2!$D$62),ISNUMBER(Scheda_2!$D$22),Scheda_2!$D$62>Scheda_2!$D$22),"ATTENZIONE: data di realizzazione successiva alla data di presentazione","")
A28: Zona rossa | B28: =IF(OR(Scheda_2!$D$119="Sì",Scheda_2!$D$98="Sì"),"ATTENZIONE: aumento di volumi abitabili o mutamento d'uso verso l'abitativo in zona rossa (LR 21/2003, sez. 17)","")
A29: K3 | B29: =IF(AND(Scheda_2!$D$193="Sì",Scheda_2!$D$29=""),"Contributo: zona omogenea A-F non determinata, indicarla nella scheda (sez. 29.3, 35)","")
A31: Regole per campo (X = sempre; P, C, DR, T = solo se la qualificazione ha quel flag, vedi Elenchi)
A32: Codice | B32: Campo | C32: Sezione | D32: ORD | E32: CON | F32: AGI | G32: ACC | H32: Pertinente | I32: Condizione | J32: Regola | K32: Obbligatorio | L32: Stato
A33: Z01 | B33: Zona sismica | C33: Dati noti per Ottaviano | H33: 1 | I33: 1 | J33: =IF($B$5="","",IF($B$5="ORD",D33,IF($B$5="CON",E33,IF($B$5="AGI",F33,G33)))) -> 0 | K33: 0 | L33: =IF(K33=0,"",IF(LEN(TRIM(Scheda_2!$D$9&""))=0,"MANCANTE",IF(LEFT(LOWER(TRIM(Scheda_2!$D$9&"")),7)="non not","NON NOTO","ok")))
A34: Z02 | B34: Zona rossa vesuviana (LR 21/2003) | C34: Dati noti per Ottaviano | H34: 1 | I34: 1 | J34: =IF($B$5="","",IF($B$5="ORD",D34,IF($B$5="CON",E34,IF($B$5="AGI",F34,G34)))) -> 0 | K34: 0 | L34: =IF(K34=0,"",IF(LEN(TRIM(Scheda_2!$D$10&""))=0,"MANCANTE",IF(LEFT(LOWER(TRIM(Scheda_2!$D$10&"")),7)="non not","NON NOTO","ok")))
A35: Z03 | B35: Vincolo paesaggistico | C35: Dati noti per Ottaviano | H35: 1 | I35: 1 | J35: =IF($B$5="","",IF($B$5="ORD",D35,IF($B$5="CON",E35,IF($B$5="AGI",F35,G35)))) -> 0 | K35: 0 | L35: =IF(K35=0,"",IF(LEN(TRIM(Scheda_2!$D$11&""))=0,"MANCANTE",IF(LEFT(LOWER(TRIM(Scheda_2!$D$11&"")),7)="non not","NON NOTO","ok")))
A36: Z04 | B36: PSAI vigente | C36: Dati noti per Ottaviano | H36: 1 | I36: 1 | J36: =IF($B$5="","",IF($B$5="ORD",D36,IF($B$5="CON",E36,IF($B$5="AGI",F36,G36)))) -> 0 | K36: 0 | L36: =IF(K36=0,"",IF(LEN(TRIM(Scheda_2!$D$12&""))=0,"MANCANTE",IF(LEFT(LOWER(TRIM(Scheda_2!$D$12&"")),7)="non not","NON NOTO","ok")))
A37: Z05 | B37: Funzioni sismiche | C37: Dati noti per Ottaviano | H37: 1 | I37: 1 | J37: =IF($B$5="","",IF($B$5="ORD",D37,IF($B$5="CON",E37,IF($B$5="AGI",F37,G37)))) -> 0 | K37: 0 | L37: =IF(K37=0,"",IF(LEN(TRIM(Scheda_2!$D$13&""))=0,"MANCANTE",IF(LEFT(LOWER(TRIM(Scheda_2!$D$13&"")),7)="non not","NON NOTO","ok")))
A38: Z06 | B38: Delibera oneri e K2 | C38: Dati noti per Ottaviano | H38: 1 | I38: 1 | J38: =IF($B$5="","",IF($B$5="ORD",D38,IF($B$5="CON",E38,IF($B$5="AGI",F38,G38)))) -> 0 | K38: 0 | L38: =IF(K38=0,"",IF(LEN(TRIM(Scheda_2!$D$14&""))=0,"MANCANTE",IF(LEFT(LOWER(TRIM(Scheda_2!$D$14&"")),7)="non not","NON NOTO","ok")))
A39: Z07 | B39: Prevalenza NTA / RUEC | C39: Dati noti per Ottaviano | H39: 1 | I39: 1 | J39: =IF($B$5="","",IF($B$5="ORD",D39,IF($B$5="CON",E39,IF($B$5="AGI",F39,G39)))) -> 0 | K39: 0 | L39: =IF(K39=0,"",IF(LEN(TRIM(Scheda_2!$D$15&""))=0,"MANCANTE",IF(LEFT(LOWER(TRIM(Scheda_2!$D$15&"")),7)="non not","NON NOTO","ok")))
A40: A01 | B40: Codice pratica anonimo (scelto dall'ufficio, senza nomi né numeri di protocollo identificativi) | C40: Procedimento | D40: X | E40: X | F40: X | G40: X | H40: 1 | I40: 1 | J40: =IF($B$5="","",IF($B$5="ORD",D40,IF($B$5="CON",E40,IF($B$5="AGI",F40,G40)))) -> X | K40: =IF(H40=1,1,0) -> 1 | L40: =IF(K40=0,"",IF(LEN(TRIM(Scheda_2!$D$18&""))=0,"MANCANTE",IF(LEFT(LOWER(TRIM(Scheda_2!$D$18&"")),7)="non not","NON NOTO","ok"))) -> ok
A41: A02 | B41: Tipo di procedimento | C41: Procedimento | D41: X | E41: X | F41: X | G41: X | H41: 1 | I41: 1 | J41: =IF($B$5="","",IF($B$5="ORD",D41,IF($B$5="CON",E41,IF($B$5="AGI",F41,G41)))) -> X | K41: =IF(H41=1,1,0) -> 1 | L41: =IF(K41=0,"",IF(LEN(TRIM(Scheda_2!$D$19&""))=0,"MANCANTE",IF(LEFT(LOWER(TRIM(Scheda_2!$D$19&"")),7)="non not","NON NOTO","ok"))) -> ok
A42: A03 | B42: Qualificazione dell'intervento (DPR 380/2001) | C42: Procedimento | D42: X | G42: X | H42: 1 | I42: 1 | J42: =IF($B$5="","",IF($B$5="ORD",D42,IF($B$5="CON",E42,IF($B$5="AGI",F42,G42)))) -> X | K42: =IF(OR(H42=0,I42=0,J42=""),0,IF(IF(J42="X",1,IF(J42="P",$B$6,IF(J42="C",$B$7,IF(J42="DR",$B$8,IF(J42="T",$B$9,0)))))=1,1,0)) -> 1 | L42: =IF(K42=0,"",IF(LEN(TRIM(Scheda_2!$D$20&""))=0,"MANCANTE",IF(LEFT(LOWER(TRIM(Scheda_2!$D$20&"")),7)="non not","NON NOTO","ok"))) -> ok
A43: A04 | B43: Descrizione sintetica delle opere (solo dati tecnici, nessun dato personale) | C43: Procedimento | D43: X | E43: X | G43: X | H43: 1 | I43: 1 | J43: =IF($B$5="","",IF($B$5="ORD",D43,IF($B$5="CON",E43,IF($B$5="AGI",F43,G43)))) -> X | K43: =IF(OR(H43=0,I43=0,J43=""),0,IF(IF(J43="X",1,IF(J43="P",$B$6,IF(J43="C",$B$7,IF(J43="DR",$B$8,IF(J43="T",$B$9,0)))))=1,1,0)) -> 1 | L43: =IF(K43=0,"",IF(LEN(TRIM(Scheda_2!$D$21&""))=0,"MANCANTE",IF(LEFT(LOWER(TRIM(Scheda_2!$D$21&"")),7)="non not","NON NOTO","ok"))) -> ok
...

Sheet Elenchi
A1: Tipo di procedimento | B1: Gruppo (ORD/CON/AGI/ACC) | D1: Qualificazione dell'intervento | E1: P: ha parametri edilizi (1/0) | F1: C: può cambiare uso/carico (1/0) | G1: DR: demolizione-ricostruzione (1/0) | H1: T: intervento tetto (1/0) | J1: Ambito PUC (articolo NTA) | K1: Art. | L1: Zona A-F di default (sez. 35.0) | M1: Colonna K3 | N1: Ambito agricolo (1/0) | Q1: SN | R1: SNNN | S1: ACQ | T1: ZONA | U1: RISCHIO | V1: INAREA | W1: PTP | X1: PARCO | Y1: FASCIA | Z1: DPR31 | AA1: CATSISM | AB1: TITORIG | AC1: EPOCA | AD1: STATOLEG | AE1: DIFFQUAL | AF1: DOCDATA | AG1: PARKUBIC | AH1: USO | AI1: PARERE | AJ1: TIPOL | AK1: LETT380 | AL1: ONERIDEF | AM1: LRTIPO | AN1: RECMAT | AO1: LEGIT | AP1: K3TIPO | AQ1: IFCLASS | AR1: PROCPAES | AS1: ANCORAGGIO | AT1: MUSO | AU1: LEGGEPEND | AV1: PTIPO | AW1: SWITCH
A2: PdC | B2: ORD | D2: Manutenzione ordinaria | E2: 0 | F2: 0 | G2: 0 | H2: 0 | J2: Art. 7 – Collinari e montani di tutela naturale | K2: 7 | L2: E | M2: E | N2: 1 | Q2: Sì | R2: Sì | S2: Acquisita | T2: A | U2: Nessuno | V2: Interamente | W2: PI | X2: Dentro | Y2: Nessuna | Z2: Nessuna voce | AA2: Rilevante | AB2: Permesso di costruire / licenza / concessione | AC2: Ante 1945 | AD2: Accertato | AE2: Assenza di titolo | AF2: Foto aeree / ortofoto | AG2: Nel lotto (in superficie) | AH2: A – Abitativo | AI2: Acquisito | AJ2: 1 – Senza titolo, non conformi | AK2: b | AL2: Sì, entro il termine | AM2: Recupero abitativo del sottotetto | AN2: Muratura | AO2: Legittimo | AP2: Residenziale (nuova costruzione) | AQ2: If < 1,50 mc/mq | AR2: Autorizzazione ordinaria (art. 146) | AS2: Ancorato stabilmente | AT2: Agricolo | AU2: L. 47/85 | AV2: Manutenzione ordinaria | AW2: Sì
A3: SCIA | B3: ORD | D3: Manutenzione straordinaria | E3: 0 | F3: 0 | G3: 0 | H3: 0 | J3: Art. 8 – Agricoli di salvaguardia | K3: 8 | L3: E | M3: E | N3: 1 | Q3: No | R3: No | S3: Non acquisita | T3: B | U3: R1 | V3: Parzialmente | W3: RUA | X3: Contiguo | Y3: Stradale | Z3: Allegato A (esclusa) | AA3: Di minore rilevanza | AB3: SCIA / DIA | AC3: 1945-1955 | AD3: Da acquisire d'ufficio | AE3: Totale difformità | AF3: Catasto storico | AG3: Interrato | AH3: B – Industriale/artigianale | AI3: Non acquisito | AJ3: 2 – Senza titolo, conformi | AK3: c | AL3: Sì, oltre il termine | AM3: Piscina interrata | AN3: Calcestruzzo | AO3: Sanato L. 47/85 | AP3: Edilizia convenzionata o sovvenzionata | AQ3: 1,50 ≤ If ≤ 3,00 mc/mq | AR3: Semplificata (DPR 31/2017) | AS3: Amovibile | AT3: Pertinenziale | AU3: L. 724/94 | AV3: Manutenzione straordinaria | AW3: No
A4: SCIA alternativa al PdC | B4: ORD | D4: Restauro e risanamento conservativo | E4: 0 | F4: 0 | G4: 0 | H4: 0 | J4: Art. 9 – Agricoli pedecollinari e di pianura | K4: 9 | L4: E | M4: E | N4: 1 | Q4: Non noto | R4: Non necessario | S4: Non necessaria | T4: B-PUA | U4: R2 | V4: No | W4: Altra zona PTP | X4: Fuori | Y4: Ferroviaria | Z4: Allegato B (semplificata) | AA4: Privo di rilevanza | AB4: Condono rilasciato | AC4: Dopo il 1955 | AE4: Variazioni essenziali | AF4: Atto o certificazione ufficiale | AG4: Fuori lotto | AH4: C – Terziario | AI4: Dissenso | AJ4: 3 – Ristrutturazione edilizia | AK4: d | AL4: No | AM4: Muro di cinta / recinzione | AN4: Rete metallica / siepe | AO4: Sanato L. 724/94 | AP4: Terziaria direzionale o commerciale | AQ4: If > 3,00 mc/mq | AR4: Scheda semplificata (DPCM 12/12/2005) | AS4: Non noto | AT4: Altro | AV4: Efficientamento energetico
A5: CILA | B5: ORD | D5: Ristrutturazione edilizia senza demolizione | E5: 1 | F5: 1 | G5: 0 | H5: 0 | J5: Art. 10 – Agricoli periurbani | K5: 10 | L5: E | M5: E | N5: 1 | R5: Non noto | S5: Non noto | T5: C | U5: R3 | V5: Non noto | W5: Fuori perimetro PTP | X5: Non noto | Y5: Fluviale o canali | Z5: Non noto | AB5: Nessun titolo (abusivo) | AC5: Non nota | AE5: Parziale difformità | AF5: Altra documentazione | AG5: Non previsti | AH5: D – Commerciale | AI5: Non richiesto | AJ5: 4 – Restauro e risanamento (zona A) | AM5: Delocalizzazione dalla zona rossa | AN5: Altro | AO5: Sanato L. 326/03 | AP5: Turistica residenziale | AR5: Non necessaria | AV5: Restauro e risanamento conservativo
A6: Edilizia libera | B6: ORD | D6: Ristrutturazione con demolizione e ricostruzione | E6: 1 | F6: 1 | G6: 1 | H6: 0 | J6: Art. 11 – Agricoli urbani | K6: 11 | L6: E | M6: E | N6: 1 | T6: D | U6: R4 | W6: Non noto | Y6: Elettrodotto | AB6: Nessun titolo (preesistente all'obbligo di titolo) | AE6: Tolleranza (art. 34-bis) | AF6: Nessuna | AH6: E – Ricettivo | AJ6: 5 – Restauro e risanamento | AM6: Altro | AO6: Non legittimo | AP6: Attrezzature di tempo libero | AR6: Non noto | AV6: Altro (eccedente)
A7: Condono L. 47/85 | B7: CON | D7: Ristrutturazione urbanistica | E7: 1 | F7: 1 | G7: 0 | H7: 0 | J7: Art. 12 – Florovivaismo | K7: 12 | L7: E | M7: E | N7: 1 | T7: E | U7: Non noto | Y7: Captazione acque | AB7: Non noto | AH7: F – Ricreativo | AJ7: 6 – Manutenzione straordinaria | AP7: Ristrutturazione con incremento di superficie
A8: Condono L. 724/94 | B8: CON | D8: Nuova costruzione | E8: 1 | F8: 1 | G8: 0 | H8: 0 | J8: Art. 14 – Recupero e valorizzazione (centri storici) | K8: 14 | L8: A | M8: A | N8: 0 | T8: F | Y8: Cimiteriale | AH8: G – Attrezzature pubbliche | AP8: Ristrutturazione con variazione d'uso
A9: Condono L. 326/03 | B9: CON | D9: Ampliamento | E9: 1 | F9: 1 | G9: 0 | H9: 0 | J9: Art. 15 – Urbani consolidati | K9: 15 | L9: B | M9: B – intervento diretto | N9: 0 | Y9: Più di una | AH9: H – Rurale | AP9: Ristrutturazione non convenzionata fuori legge
A10: Agibilità | B10: AGI | D10: Sopraelevazione | E10: 1 | F10: 1 | G10: 0 | H10: 0 | J10: Art. 16 – Urbani di riassetto, parti edificate | K10: 16 | L10: B | M10: B – intervento diretto | N10: 0 | Y10: Non noto | AP10: Ristrutturazione urbanistica (foglio ufficio)
A11: Accertamento di conformità art. 36 | B11: ACC | D11: Cambio d'uso senza opere | E11: 0 | F11: 1 | G11: 0 | H11: 0 | J11: Art. 16 – Urbani di riassetto, parti libere soggette a PUA | K11: 16 | L11: B-PUA | M11: B – PUA (foglio ufficio) | N11: 0 | AP11: Impianti industriali e artigianali
A12: Accertamento di conformità art. 36-bis | B12: ACC | D12: Cambio d'uso con opere | E12: 1 | F12: 1 | G12: 0 | H12: 0 | J12: Art. 17 – Ambiti di trasformabilità (disposizioni generali) | K12: 17 | M12: non in tabella 35.0: indicare la zona | N12: 0 | AP12: Altro (descrivere)
D13: Intervento «tetto» (copertura piana → tetto) | E13: 1 | F13: 0 | G13: 0 | H13: 1 | J13: Art. 18 – Trasformabilità strategica ATS-1 (decaduto), ATS-3, 4, 5 | K13: 18 | L13: C | M13: C | N13: 0
D14: Recupero abitativo del sottotetto | E14: 1 | F14: 1 | G14: 0 | H14: 0 | J14: Art. 19 – Trasformabilità integrata (ATI) | K14: 19 | L14: C | M14: C | N14: 0
D15: Pertinenze e manufatti (tettoie, autorimesse, volumi tecnici) | E15: 1 | F15: 0 | G15: 0 | H15: 0 | J15: Art. 20 – Produttive esistenti interne | K15: 20 | L15: D | M15: D | N15: 0
D16: Demolizione senza ricostruzione | E16: 0 | F16: 0 | G16: 0 | H16: 0 | J16: Art. 21 – Produttive esistenti esterne | K16: 21 | L16: D | M16: D | N16: 0
D17: Altro (specificare nella descrizione) | E17: 1 | F17: 1 | G17: 0 | H17: 0 | J17: Art. 22 – Produttive di riassetto e completamento | K17: 22 | L17: D | M17: D | N17: 0
J18: Art. 23 – Produttive incompatibili | K18: 23 | L18: D | M18: D | N18: 0
J19: Art. 24 – Produttive dismesse | K19: 24 | L19: D | M19: D | N19: 0
J20: Art. 25 – Distributori di carburante | K20: 25 | L20: D | M20: D | N20: 0
J21: Art. 26 – Attività turistiche e ricettive esistenti | K21: 26 | L21: B | M21: B – intervento diretto | N21: 0
J22: Art. 27 – Trasformabilità per attività produttive (ATP) | K22: 27 | L22: D | M22: D | N22: 0
J23: Art. 28 – Attrezzature pubbliche locali | K23: 28 | L23: F | M23: F | N23: 0
J24: Artt. 29 e 47 – Attrezzature pubbliche territoriali | K24: 29 | L24: F | M24: F | N24: 0
J25: Art. 30 – Attrezzature private esistenti | K25: 30 | L25: F | M25: F | N25: 0
J26: Art. 30 bis – Attrezzature private dismesse | K26: 30 bis | L26: F | M26: F | N26: 0
J27: Art. 31 – Servizi generali e impianti tecnologici | K27: 31 | L27: F | M27: F | N27: 0
J28: Artt. 32-35 – Sistema infrastrutturale (nessuna zona) | K28: 32-35 | M28: nessuna corrispondenza | N28: 0
J29: Altro / non noto | N29: 0
J31: Default = assimilazione ambiti NTA → zone DM 1444/68 (sez. 35.0, decisioni dell'utente del 19/10/2026): non è una norma; se la scheda indica la zona, prevale.
